<?xml version="1.0" ?>
<robot name="my" xmlns:xacro="http://www.ros.org/wiki/xacro">

<xacro:include filename="$(find maker_robot)/urdf/materials.xacro" />
 <material name="blue">
	    <color rgba="0 0 0.8 0.6"/>
    </material>

<link name="base_link">
 <collision>
          <origin rpy="0 0 0" xyz="0 0 0.0005"/>
          <geometry>
            <box size="0.54 0.55 0.001"/>
          </geometry>
  </collision>
</link>

<joint name="base_link_joint" type="fixed">
        <origin rpy="0 0 -1.5708" xyz="0 0 0.1" />
        <parent link="base_link" />
        <child link="base_plate" />
</joint>
<!--
<link name="base_plate">
 <visual>
   <origin rpy="0 0 0" xyz="0 0 1.0"/>
    <geometry>
      <box size="0.4 0.35 0.001"/>
     
    </geometry>
   <material name="blue"/>
 </visual>
  <collision>
    <origin rpy="0 0 0" xyz="0 0 0.0"/>
   <geometry>
      <box size="0.4 0.35 0.001"/>
    </geometry>

  </collision>
</link>
-->

<link name="base_plate">
  
  <visual>
    <origin rpy="0 0 0" xyz="0 0 -0.1"/>
    <geometry>
      <mesh filename="package://maker_robot/meshes_2/base_plate.stl" scale="0.001 0.001 0.001"/>
    </geometry>
    <material name="blue"/>
  </visual>
  <collision>
    <origin rpy="0 0 0" xyz="0 0 -0.1"/>
    <geometry>
      <mesh filename="package://maker_robot/meshes_2/base_plate.stl" scale="0.001 0.001 0.001"/>
    </geometry>
  </collision>
</link>

<link name="right_front_wheel">
  
  <visual>
    <origin rpy="0 0 0" xyz="-0.175 0.17 -0.1"/>
    <geometry>
      <mesh filename="package://maker_robot/meshes_2/right_front_wheel.stl" scale="0.001 0.001 0.001"/>
    </geometry>
    <material name="silver"/>
  </visual>
  <collision>
    <origin rpy="0 0 0" xyz="-0.175 0.17 -0.1"/>
    <geometry>
      <mesh filename="package://maker_robot/meshes_2/right_front_wheel.stl" scale="0.001 0.001 0.001"/>
    </geometry>
  </collision>
</link>

<link name="right_rear_wheel">
 
  <visual>
    <origin rpy="0 0 0" xyz="-0.175 -0.18 -0.1"/>
    <geometry>
      <mesh filename="package://maker_robot/meshes_2/right_rear_wheel.stl" scale="0.001 0.001 0.001"/>
    </geometry>
    <material name="silver"/>
  </visual>
  <collision>
    <origin rpy="0 0 0" xyz="-0.175 -0.18 -0.1"/>
    <geometry>
      <mesh filename="package://maker_robot/meshes_2/right_rear_wheel.stl" scale="0.001 0.001 0.001"/>
    </geometry>
  </collision>
</link>

<link name="left_front_wheel">
  <visual>
    <origin rpy="0 0 0" xyz="0.175 0.17 -0.1"/>
    <geometry>
      <mesh filename="package://maker_robot/meshes_2/left_front_wheel.stl" scale="0.001 0.001 0.001"/>
    </geometry>
    <material name="silver"/>
  </visual>
  <collision>
    <origin rpy="0 0 0" xyz="0.175 0.17 -0.1"/>
    <geometry>
      <mesh filename="package://maker_robot/meshes_2/left_front_wheel.stl" scale="0.001 0.001 0.001"/>
    </geometry>
  </collision>
</link>

<link name="left_rear_wheel">

  <visual>
    <origin rpy="0 0 0" xyz="0.175 -0.18 -0.1"/>
    <geometry>
      <mesh filename="package://maker_robot/meshes_2/left_rear_wheel.stl" scale="0.001 0.001 0.001"/>
    </geometry>
    <material name="silver"/>
  </visual>
  <collision>
    <origin rpy="0 0 0" xyz="0.175 -0.18 -0.1"/>
    <geometry>
      <mesh filename="package://maker_robot/meshes_2/left_rear_wheel.stl" scale="0.001 0.001 0.001"/>
    </geometry>
  </collision>
</link>

<joint name="Rev1" type="continuous">
  <origin rpy="0 0 0" xyz="0.175 -0.17 0.0"/>
  <parent link="base_plate"/>
  <child link="right_front_wheel"/>
  <axis xyz="1.0 0.0 0.0"/>
</joint>

<joint name="Rev2" type="continuous">
  <origin rpy="0 0 0" xyz="0.175 0.18 0.0"/>
  <parent link="base_plate"/>
  <child link="right_rear_wheel"/>
  <axis xyz="1.0 0.0 0.0"/>
</joint>

<joint name="Rev3" type="continuous">
  <origin rpy="0 0 0" xyz="-0.175 -0.17 0.0"/>
  <parent link="base_plate"/>
  <child link="left_front_wheel"/>
  <axis xyz="-1.0 0.0 0.0"/>
</joint>

<joint name="Rev4" type="continuous">
  <origin rpy="0 0 0" xyz="-0.175 0.18 0.0"/>
  <parent link="base_plate"/>
  <child link="left_rear_wheel"/>
  <axis xyz="-1.0 0.0 0.0"/>
</joint>

</robot>
